Workbook
Name Divisor_Cr: Financials!$M$6

Sheet Cover
A2: Emirates NBD - RBL Bank Deal Analysis
D4: RBL BANK VALUATION (DDM) | I4: NSE : RBLBANK
D6: Intrinsic Value | E6: 83.72
D7: Current Market Price | E7: 292
D8: Implied Downside | E8: =(E6-E7)/E7 -> -0.71328767
A11: Name : | B11: Vedaansh Mittal | G11: Date : | H11: March 2026
A12: Course : | B12: (Bcom.H), KMV - DU
A16: Summary : | B16: The DDM valuation of RBL Bank yields an intrinsic value of approximately ₹84 per share, compared to the current market price of ₹292. This suggests that the stock is overvalued based on dividend-based valuation.
B18: The bank shows moderate profitability with improving ROE and stable NIM, while capital adequacy remains strong. However, lower dividend payouts and growth assumptions limit the valuation upside.
B20: Overall, the model indicates that RBL Bank is currently trading above its intrinsic value, and the market appears to be factoring in stronger future growth and/or higher payout expectations than those assumed in this model.
B21: Additionally, dividend discount models may undervalue banks with low payout ratios, as retained earnings contribute significantly to future growth.
B23: The valuation is sensitive to assumptions such as cost of equity and terminal growth rate.
A25: Event Disclosure : | B25: This DDM valuation is based on RBL Bank's standalone historical performance and does not fully incorporate the pending ₹26,853 crore ($3 billion) capital infusion from Emirates NBD.

Sheet Raw Data
A2: Line item | B2: Units | C2: Mar 23 | D2: Mar 24 | E2: Mar 25
A3: Income Statement (Consolidated)
A4: Interest Earned
A5: Int on Advances | B5: ₹ ‘000s | C5: 76763582 | D5: 99776574 | E5: 112247590
A6: Int on Investments | B6: ₹ ‘000s | C6: 16256472 | D6: 20340462 | E6: 21474070
A7: Interbank Int | B7: ₹ ‘000s | C7: 2654523 | D7: 1617672 | E7: 3024516
A8: Others | B8: ₹ ‘000s | C8: 1091487 | D8: 2203252 | E8: 3664927
A9: Interest Expended | B9: ₹ ‘000s
A10: Interest on Deposits | B10: ₹ ‘000s | C10: 40064082 | D10: 53428530 | E10: 65768669
A11: Interest on Bal with RBI and Inter bank Funds | B11: ₹ ‘000s | C11: 764593 | D11: 2771060 | E11: 3766717
A12: Others | B12: ₹ ‘000s | C12: 5957558 | D12: 7300877 | E12: 6226476
A13: Other Income | B13: ₹ ‘000s
A14: Commission, Exchange and Brokerage | B14: ₹ ‘000s | C14: 21045882 | D14: 26053604 | E14: 30471213
A15: Profit/(Loss) on sale of Investments (Net) | B15: ₹ ‘000s | C15: 1222032 | D15: 1358323 | E15: 3475237
A16: Profit/(Loss) on revaluation of Investment (Net) | B16: ₹ ‘000s | C16: 71036 | D16: 229809 | E16: 214926
A17: Profit/(Loss) on sale of land, building and other assets (Net) | B17: ₹ ‘000s | C17: -3792 | D17: 4797 | E17: 10310
A18: Profit/(Loss) on Exchange Transactions | B18: ₹ ‘000s | C18: 2692495 | D18: 2668655 | E18: 3541676
A19: Income earned by way of dividends, etc. from subsidiaries/companies and/or joint ventures abroad/ in India | B19: ₹ ‘000s | C19: 0 | D19: 0 | E19: 0
A20: Misc Income | B20: ₹ ‘000s | C20: 41607 | D20: 284331 | E20: 70449
A21: Operating Expenses | B21: ₹ ‘000s | C21: 52618191 | D21: 59765197 | E21: 65888431
A22: Provision and Contingencies | B22: ₹ cr
A23: Provision towards NPA (Advances) | B23: ₹ cr | C23: 1121.8 | D23: 1356.52 | E23: 3104.93
A24: Provision towards NPA (Investment) | B24: ₹ cr | C24: 67.5 | D24: 131.07 | E24: -164.72
A25: Provision towards Standard Assets | B25: ₹ cr | C25: -221.72 | D25: 287.08 | E25: 11.37
A26: Provision for Others | B26: ₹ cr | C26: 54.37 | D26: 3.8 | E26: 7.09
A27: Provision towards Income Tax | B27: ₹ cr | C27: 272.47 | D27: 104.93 | E27: 68.28
A28: Provision towards Deferred Tax (Net) | B28: ₹ cr | C28: 29.13 | D28: -16.11 | E28: -89.55
A30: Balance Sheet (Consolidated)
A31: Capital and Liabilities
A32: Capital | B32: ₹ ‘000s | C32: 5995681 | D32: 6050999 | E32: 6078761
A33: ESOP Outstanding | B33: ₹ ‘000s | C33: 0 | D33: 1176947 | E33: 1698674
A34: Reserves and Surplus | B34: ₹ ‘000s | C34: 129260906 | D34: 141146428 | E34: 148917819
A35: Deposits | B35: ₹ ‘000s | C35: 848747377 | D35: 1034704359 | E35: 1109329023
A36: Borrowings | B36: ₹ ‘000s | C36: 133317407 | D36: 141852485 | E36: 137349800
A37: Other Liabilities and Provisions | B37: ₹ ‘000s | C37: 40735743 | D37: 59607979 | E37: 64347047
A38: Assets | B38: ₹ ‘000s
A39: Goodwill on Consolidation | B39: ₹ ‘000s | C39: 406776 | D39: 406776 | E39: 406776
A40: Cash and Balances with Reserve Bank of India | B40: ₹ ‘000s | C40: 62380555 | D40: 120708226 | E40: 109647567
A41: Balances with Banks and Money at Call and Short Notice | B41: ₹ ‘000s | C41: 22891311 | D41: 23526020 | E41: 16016263
A42: Investments | B42: ₹ ‘000s | C42: 287302615 | D42: 294777602 | E42: 321030929
...

Sheet Financials
B4: INCOME STATEMENT | L4: Reporting Unit (Raw Data) | M4: ₹ in ‘000s
B5: Metric | C5: Units (₹ cr) | D5: Mar 23 | E5: Mar 24 | F5: Mar 25 | G5: Mar 26E | H5: Mar 27E | I5: Mar 28E | L5: Target Unit (Financials) | M5: ₹ in crore
B6: Interest on Advances | D6: ='Raw Data'!C5/Divisor_Cr -> 7676.3582 | E6: ='Raw Data'!D5/Divisor_Cr -> 9977.6574 | F6: ='Raw Data'!E5/Divisor_Cr -> 11224.759 | G6: =((Schedule!G8+Schedule!F8)/2)*Assumptions!D31 -> 12479.756 | H6: =((Schedule!H8+Schedule!G8)/2)*Assumptions!E31 -> 13809.384 | I6: =((Schedule!I8+Schedule!H8)/2)*Assumptions!F31 -> 15354.93 | L6: Divisor_Cr | M6: 10000
B7: Interest on Investments | D7: ='Raw Data'!C6/Divisor_Cr -> 1625.6472 | E7: ='Raw Data'!D6/Divisor_Cr -> 2034.0462 | F7: ='Raw Data'!E6/Divisor_Cr -> 2147.407 | G7: =((Schedule!G23+Schedule!F23)/2)*Assumptions!D32 -> 2317.3193 | H7: =((Schedule!H23+Schedule!G23)/2)*Assumptions!E32 -> 2417.5748 | I7: =((Schedule!I23+Schedule!H23)/2)*Assumptions!F32 -> 2548.7638
B8: Interest on Bal with RBI and Inter bank Funds | D8: ='Raw Data'!C7/Divisor_Cr -> 265.4523 | E8: ='Raw Data'!D7/Divisor_Cr -> 161.7672 | F8: ='Raw Data'!E7/Divisor_Cr -> 302.4516 | G8: =((Schedule!G31+Schedule!F31)/2)*Assumptions!D33 -> 110.28826 | H8: =((Schedule!H31+Schedule!G31)/2)*Assumptions!E33 -> 132.57008 | I8: =((Schedule!I31+Schedule!H31)/2)*Assumptions!F33 -> 149.80419
B9: Others | D9: ='Raw Data'!C8/Divisor_Cr -> 109.1487 | E9: ='Raw Data'!D8/Divisor_Cr -> 220.3252 | F9: ='Raw Data'!E8/Divisor_Cr -> 366.4927 | G9: =F9*(1+Assumptions!$D$28) -> 381.15241 | H9: =G9*(1+Assumptions!$D$28) -> 396.3985 | I9: =H9*(1+Assumptions!$D$28) -> 412.25444
B10: Interest Income | D10: =SUM(D6:D9) -> 9676.6064 | E10: =SUM(E6:E9) -> 12393.796 | F10: =SUM(F6:F9) -> 14041.11 | G10: =SUM(G6:G9) -> 15288.516 | H10: =SUM(H6:H9) -> 16755.927 | I10: =SUM(I6:I9) -> 18465.752
B11: Interest on Deposits | D11: ='Raw Data'!C10/Divisor_Cr -> 4006.4082 | E11: ='Raw Data'!D10/Divisor_Cr -> 5342.853 | F11: ='Raw Data'!E10/Divisor_Cr -> 6576.8669 | G11: =((Schedule!G14+Schedule!F14)/2)*(Financials!F11/((Schedule!F14+Schedule!E14)/2)) -> 7180.0975 | H11: =((Schedule!H14+Schedule!G14)/2)*(Financials!G11/((Schedule!G14+Schedule!F14)/2)) -> 8007.6803 | I11: =((Schedule!I14+Schedule!H14)/2)*(Financials!H11/((Schedule!H14+Schedule!G14)/2)) -> 8968.6019
B12: Interest on Bal with RBI and Inter bank Funds | D12: ='Raw Data'!C11/Divisor_Cr -> 76.4593 | E12: ='Raw Data'!D11/Divisor_Cr -> 277.106 | F12: ='Raw Data'!E11/Divisor_Cr -> 376.6717 | G12: =Assumptions!D33*((Schedule!G31+Schedule!F31)/2) -> 110.28826 | H12: =Assumptions!E33*((Schedule!H31+Schedule!G31)/2) -> 132.57008 | I12: =Assumptions!F33*((Schedule!I31+Schedule!H31)/2) -> 149.80419
B13: Others | D13: ='Raw Data'!C12/Divisor_Cr -> 595.7558 | E13: ='Raw Data'!D12/Divisor_Cr -> 730.0877 | F13: ='Raw Data'!E12/Divisor_Cr -> 622.6476 | G13: =F13*(1+Assumptions!$D$28) -> 647.5535 | H13: =G13*(1+Assumptions!$D$28) -> 673.45564 | I13: =H13*(1+Assumptions!$D$28) -> 700.39387
B14: Interest Expenses | D14: =SUM(D11+D12+D13) -> 4678.6233 | E14: =SUM(E11+E12+E13) -> 6350.0467 | F14: =SUM(F11+F12+F13) -> 7576.1862 | G14: =SUM(G11:G13) -> 7937.9393 | H14: =SUM(H11:H13) -> 8813.706 | I14: =SUM(I11:I13) -> 9818.8
B15: Net Interest Income (NII) | D15: =D10-D14 -> 4997.9831 | E15: =E10-E14 -> 6043.7493 | F15: =F10-F14 -> 6464.9241 | G15: =G10-G14 -> 7350.5768 | H15: =H10-H14 -> 7942.221 | I15: =I10-I14 -> 8646.9523
B17: Commission, Exchange and Brokerage | D17: ='Raw Data'!C14/Divisor_Cr -> 2104.5882 | E17: ='Raw Data'!D14/Divisor_Cr -> 2605.3604 | F17: ='Raw Data'!E14/Divisor_Cr -> 3047.1213 | G17: =F17*(1+Assumptions!$D$28) -> 3169.0062 | H17: =G17*(1+Assumptions!$D$28) -> 3295.7664 | I17: =H17*(1+Assumptions!$D$28) -> 3427.5971
B18: Profit/(Loss) on sale of Investments (Net) | D18: ='Raw Data'!C15/Divisor_Cr -> 122.2032 | E18: ='Raw Data'!D15/Divisor_Cr -> 135.8323 | F18: ='Raw Data'!E15/Divisor_Cr -> 347.5237 | G18: =(F18+E18+D18)/3 -> 201.85307 | H18: =(F18+E18+D18)/3 -> 201.85307 | I18: =(F18+E18+D18)/3 -> 201.85307
B19: Profit/(Loss) on revaluation of Investment (Net) | D19: ='Raw Data'!C16/Divisor_Cr -> 7.1036 | E19: ='Raw Data'!D16/Divisor_Cr -> 22.9809 | F19: ='Raw Data'!E16/Divisor_Cr -> 21.4926 | G19: =0 -> 0 | H19: =0 -> 0 | I19: =0 -> 0
B20: Profit/(Loss) on sale of land, building and other assets (Net) | D20: ='Raw Data'!C17/Divisor_Cr -> -0.3792 | E20: ='Raw Data'!D17/Divisor_Cr -> 0.4797 | F20: ='Raw Data'!E17/Divisor_Cr -> 1.031 | G20: =0 -> 0 | H20: =0 -> 0 | I20: =0 -> 0
B21: Profit/(Loss) on Exchange Transactions | D21: ='Raw Data'!C18/Divisor_Cr -> 269.2495 | E21: ='Raw Data'!D18/Divisor_Cr -> 266.8655 | F21: ='Raw Data'!E18/Divisor_Cr -> 354.1676 | G21: =($F$21/$F$10)*G10 -> 385.63169 | H21: =($F$21/$F$10)*H10 -> 422.6451 | I21: =($F$21/$F$10)*I10 -> 465.77308
B22: Income earned by way of dividends, etc. from subsidiaries/companies and/or joint ventures abroad/ in India this is the item | D22: ='Raw Data'!C19/Divisor_Cr -> 0 | E22: ='Raw Data'!D19/Divisor_Cr -> 0 | F22: ='Raw Data'!E19/Divisor_Cr -> 0 | G22: =0 -> 0 | H22: =0 -> 0 | I22: =0 -> 0
B23: Misc Income | D23: ='Raw Data'!C20/Divisor_Cr -> 4.1607 | E23: ='Raw Data'!D20/Divisor_Cr -> 28.4331 | F23: ='Raw Data'!E20/Divisor_Cr -> 7.0449 | G23: =F23*(1+Assumptions!$D$28) -> 7.326696 | H23: =G23*(1+Assumptions!$D$28) -> 7.6197638 | I23: =H23*(1+Assumptions!$D$28) -> 7.9245544
B24: Total Other Income | D24: =SUM(D17:D23) -> 2506.926 | E24: =SUM(E17:E23) -> 3059.9519 | F24: =SUM(F17:F23) -> 3778.3811 | G24: =SUM(G17:G23) -> 3763.8176 | H24: =SUM(H17:H23) -> 3927.8843 | I24: =SUM(I17:I23) -> 4103.1478
B25: Net Total Reveue | D25: =D15+D24 -> 7504.9091 | E25: =E15+E24 -> 9103.7012 | F25: =F15+F24 -> 10243.305 | G25: =G24+G15 -> 11114.394 | H25: =H24+H15 -> 11870.105 | I25: =I24+I15 -> 12750.1
B27: (Operating Expenses) | D27: =-'Raw Data'!C21/Divisor_Cr -> -5261.8191 | E27: =-'Raw Data'!D21/Divisor_Cr -> -5976.5197 | F27: =-'Raw Data'!E21/Divisor_Cr -> -6588.8431 | G27: =-1*(Assumptions!D13*Financials!G25) -> -6890.9245 | H27: =-1*(Assumptions!E13*Financials!H25) -> -7122.0632 | I27: =-1*(Assumptions!F13*Financials!I25) -> -7395.058
B28: Pre Provision Operating Profit (PPOP) | D28: =D25+D27 -> 2243.09 | E28: =E25+E27 -> 3127.1815 | F28: =F25+F27 -> 3654.4621 | G28: =SUM(G27+G25) -> 4223.4699 | H28: =SUM(H27+H25) -> 4748.0421 | I28: =SUM(I27+I25) -> 5355.042
B29: (Provisions and Contingencies) | D29: =-SUM('Raw Data'!C23:C26) -> -1021.95 | E29: =-SUM('Raw Data'!D23:D26) -> -1778.47 | F29: =-SUM('Raw Data'!E23:E26) -> -2958.67 | G29: =-1*(Assumptions!D14*Schedule!G8) -> -1867.1843 | H29: =-1*(Assumptions!E14*Schedule!H8) -> -1758.2652 | I29: =-1*(Assumptions!F14*Schedule!I8) -> -1721.9277
B30: PBT | D30: =D28+D29 -> 1221.14 | E30: =E28+E29 -> 1348.7115 | F30: =F28+F29 -> 695.7921 | G30: =G28+G29 -> 2356.2856 | H30: =H28+H29 -> 2989.7769 | I30: =I28+I29 -> 3633.1143
B31: (Tax) | D31: =-SUM('Raw Data'!C27:C28) -> -301.6 | E31: =-SUM('Raw Data'!D27:D28) -> -88.82 | F31: =-1*SUM('Raw Data'!E27:E28) -> 21.27 | G31: =-1*(G30*Assumptions!D18) -> -589.0714 | H31: =-1*(H30*Assumptions!E18) -> -747.44424 | I31: =-1*(I30*Assumptions!F18) -> -908.27858
B32: Net Profit (PAT) | D32: =SUM(D30,D31) -> 919.54 | E32: =SUM(E30,E31) -> 1259.8915 | F32: =SUM(F30,F31) -> 717.0621 | G32: =SUM(G31,G30) -> 1767.2142 | H32: =SUM(H31,H30) -> 2242.3327 | I32: =SUM(I31,I30) -> 2724.8357
B34: Weighted Average Shares (Diluted) | D34: 601995371 | E34: 613444193 | F34: 609736584 | G34: =F34 -> 609736584 | H34: =F34 -> 609736584 | I34: =F34 -> 609736584
B35: EPS (Diluted) | D35: =(D32*10000000)/D34 -> 15.274868 | E35: =(E32*10000000)/E34 -> 20.537997 | F35: =(F32*10000000)/F34 -> 11.760195 | G35: =(G32*10000000)/G34 -> 28.98324 | H35: =(H32*10000000)/H34 -> 36.775433 | I35: =(I32*10000000)/I34 -> 44.688736
B37: BALANCE SHEET
B38: Metric | C38: Units (₹ cr) | D38: Mar 23 | E38: Mar 24 | F38: Mar 25 | G38: Mar 26E | H38: Mar 27E | I38: Mar 28E
B39: EQUITY
B40: Share Capital | D40: ='Raw Data'!C32/Divisor_Cr -> 599.5681 | E40: ='Raw Data'!D32/Divisor_Cr -> 605.0999 | F40: ='Raw Data'!E32/Divisor_Cr -> 607.8761 | G40: =F40 -> 607.8761 | H40: =F40 -> 607.8761 | I40: =F40 -> 607.8761
B41: Employee Stock Option Outstanding | D41: ='Raw Data'!C33/Divisor_Cr -> 0 | E41: ='Raw Data'!D33/Divisor_Cr -> 117.6947 | F41: ='Raw Data'!E33/Divisor_Cr -> 169.8674 | G41: =F41 -> 169.8674 | H41: =F41 -> 169.8674 | I41: =F41 -> 169.8674
B42: Reserves and Surplus | D42: ='Raw Data'!C34/Divisor_Cr -> 12926.091 | E42: ='Raw Data'!D34/Divisor_Cr -> 14114.643 | F42: ='Raw Data'!E34/Divisor_Cr -> 14891.782 | G42: =F42+G32+Schedule!G83 -> 16437.521 | H42: =G42+H32+Schedule!H83 -> 18305.042 | I42: =H42+I32+Schedule!I83 -> 20464.665
B43: Total Equity | D43: =SUM(D40:D42) -> 13525.659 | E43: =SUM(E40:E42) -> 14837.437 | F43: =SUM(F40:F42) -> 15669.525 | G43: =SUM(G40:G42) -> 17215.264 | H43: =SUM(H40:H42) -> 19082.786 | I43: =SUM(I40:I42) -> 21242.409
B45: FUNDING
B46: Deposits | D46: ='Raw Data'!C35/Divisor_Cr -> 84874.738 | E46: ='Raw Data'!D35/Divisor_Cr -> 103470.44 | F46: ='Raw Data'!E35/Divisor_Cr -> 110932.9 | G46: =Schedule!G14 -> 123135.52 | H46: =Schedule!H14 -> 137911.78 | I46: =Schedule!I14 -> 154461.2
B47: Borrowings | D47: ='Raw Data'!C36/Divisor_Cr -> 13331.741 | E47: ='Raw Data'!D36/Divisor_Cr -> 14185.248 | F47: ='Raw Data'!E36/Divisor_Cr -> 13734.98 | G47: =G46*(((D47/D46)+(E47/E46)+(F47/F46))/3) -> 17156.209 | H47: =H46*(((D47/D46)+(E47/E46)+(F47/F46))/3) -> 19214.954 | I47: =I46*(((D47/D46)+(E47/E46)+(F47/F46))/3) -> 21520.749
B48: Total Funding | D48: =SUM(D46:D47) -> 98206.478 | E48: =SUM(E46:E47) -> 117655.68 | F48: =SUM(F46:F47) -> 124667.88 | G48: =SUM(G47,G46) -> 140291.73 | H48: =SUM(H47,H46) -> 157126.74 | I48: =SUM(I47,I46) -> 175981.95
...

Sheet Schedule
B2: SCHEDULES
B5: Metrics | C5: Units | D5: FY23 | E5: FY24 | F5: FY25 | G5: FY26E | H5: FY27E | I5: FY28E
B6: ADVANCES (LOANS)
B8: Advances | D8: =Financials!D56 -> 70186.435 | E8: =Financials!E56 -> 83986.915 | F8: =Financials!F56 -> 92618.267 | G8: =F8*(1+Assumptions!D6) -> 103732.46 | H8: =G8*(1+Assumptions!E6) -> 117217.68 | I8: =H8*(1+Assumptions!F6) -> 132455.98
B9: Loan Growth % | D9: =(70186.44/60004.5657)-1 -> 0.16968499 | E9: =(E8/D8)-1 -> 0.19662602 | F9: =(F8/E8)-1 -> 0.10277021 | G9: =Assumptions!D6 -> 0.12 | H9: =Assumptions!E6 -> 0.13 | I9: =Assumptions!F6 -> 0.13
B12: DEPOSITS
B14: Deposits | D14: =Financials!D46 -> 84874.738 | E14: =Financials!E46 -> 103470.44 | F14: =Financials!F46 -> 110932.9 | G14: =F14*(1+Assumptions!D7) -> 123135.52 | H14: =G14*(1+Assumptions!E7) -> 137911.78 | I14: =H14*(1+Assumptions!F7) -> 154461.2
B15: Deposit Growth % | D15: =(84874.74/79006.3571)-1 -> 0.074277351 | E15: =(E14/D14)-1 -> 0.2190958 | F15: =(F14/E14)-1 -> 0.072121726 | G15: =Assumptions!D7 -> 0.11 | H15: =Assumptions!E7 -> 0.12 | I15: =Assumptions!F7 -> 0.12
B17: Breakdown
B18: Term Deposits % | D18: ='Raw Data'!C65/'Raw Data'!C66 -> 0.62645277 | E18: ='Raw Data'!D65/'Raw Data'!D66 -> 0.64786874 | F18: ='Raw Data'!E65/'Raw Data'!E66 -> 0.65857606 | G18: =F18 -> 0.65857606 | H18: =G18 -> 0.65857606 | I18: =H18 -> 0.65857606
B21: INVESTMENTS
B23: Investments | D23: =Financials!D57 -> 28730.262 | E23: =Financials!E57 -> 29477.76 | F23: =Financials!F57 -> 32103.093 | G23: =F23*(1+Assumptions!D8) -> 34350.309 | H23: =G23*(1+Assumptions!E8) -> 36754.831 | I23: =H23*(1+Assumptions!F8) -> 39327.669
B24: Investment Growth % | D24: =(28730.26/22129.16)-1 -> 0.29829872 | E24: =(E23/D23)-1 -> 0.026017817 | F24: =(F23/E23)-1 -> 0.089061472 | G24: =Assumptions!D8 -> 0.07 | H24: =Assumptions!E8 -> 0.07 | I24: =Assumptions!F8 -> 0.07
B27: EARNING ASSETS
B29: Advances | D29: =Financials!D56 -> 70186.435 | E29: =Financials!E56 -> 83986.915 | F29: =Financials!F56 -> 92618.267 | G29: =G8 -> 103732.46 | H29: =H8 -> 117217.68 | I29: =I8 -> 132455.98
B30: Investments | D30: =Financials!D57 -> 28730.262 | E30: =Financials!E57 -> 29477.76 | F30: =Financials!F57 -> 32103.093 | G30: =G23 -> 34350.309 | H30: =H23 -> 36754.831 | I30: =I23 -> 39327.669
B31: Balance with Bank | D31: =Financials!D58 -> 2289.1311 | E31: =Financials!E58 -> 2352.602 | F31: =Financials!F58 -> 1601.6263 | G31: =G8*2% -> 2074.6492 | H31: =H8*2% -> 2344.3536 | I31: =I8*2% -> 2649.1195
B32: Total Earning Assets | D32: =SUM(D29:D31) -> 101205.83 | E32: =SUM(E29:E31) -> 115817.28 | F32: =SUM(F29:F31) -> 126322.99 | G32: =SUM(G29:G31) -> 140157.42 | H32: =SUM(H29:H31) -> 156316.86 | I32: =SUM(I29:I31) -> 174432.77
B34: NET INTEREST INCOME
B36: Average Earning Assets | D36: 187785.75 | E36: =(E32+D32)/2 -> 108511.55 | F36: =(F32+E32)/2 -> 121070.13 | G36: =(G32+F32)/2 -> 133240.2 | H36: =(H32+G32)/2 -> 148237.14 | I36: =(I32+H32)/2 -> 165374.81
B37: Net Interest Margin % | D37: =D38/D36 -> 0.026615348 | E37: =E38/E36 -> 0.055696828 | F37: =F38/F36 -> 0.053398175 | G37: =Assumptions!D12 -> 0.053 | H37: =Assumptions!E12 -> 0.0525 | I37: =Assumptions!F12 -> 0.052
B38: Net Interest Income | D38: =Financials!D15 -> 4997.9831 | E38: =Financials!E15 -> 6043.7493 | F38: =Financials!F15 -> 6464.9241 | G38: =G37*G36 -> 7061.7307 | H38: =H37*H36 -> 7782.4499 | I38: =I37*I36 -> 8599.4904
B41: NON INTEREST INCOME
B43: Non Interest Income % of Earning Assets | D43: =D45/D44 -> 0.02477057 | E43: =E45/E44 -> 0.026420513 | F43: =F45/F44 -> 0.02991048 | G43: =Assumptions!D15 -> 0.029 | H43: =Assumptions!E15 -> 0.03 | I43: =Assumptions!F15 -> 0.03
B44: Earning Assets | D44: =D32 -> 101205.83 | E44: =E32 -> 115817.28 | F44: =F32 -> 126322.99 | G44: =G32 -> 140157.42 | H44: =H32 -> 156316.86 | I44: =I32 -> 174432.77
B45: Non Interest Income | D45: =Financials!D24 -> 2506.926 | E45: =Financials!E24 -> 3059.9519 | F45: =Financials!F24 -> 3778.3811 | G45: =G43*G44 -> 4064.5651 | H45: =H43*H44 -> 4689.5059 | I45: =I43*I44 -> 5232.983
B48: OPERATING EXPENSES
B50: Cost to Income % | D50: =ABS(D52/D51) -> 0.70111697 | E50: =ABS(E52/E51) -> 0.65649339 | F50: =ABS(F52/F51) -> 0.64323409 | G50: =Assumptions!D13 -> 0.62 | H50: =Assumptions!E13 -> 0.6 | I50: =Assumptions!F13 -> 0.58
B51: Net Total Revenue | D51: =Financials!D25 -> 7504.9091 | E51: =Financials!E25 -> 9103.7012 | F51: =Financials!F25 -> 10243.305 | G51: =(G45+G38) -> 11126.296 | H51: =(H45+H38) -> 12471.956 | I51: =(I45+I38) -> 13832.473
B52: Operating Expenses | D52: =Financials!D27 -> -5261.8191 | E52: =Financials!E27 -> -5976.5197 | F52: =Financials!F27 -> -6588.8431 | G52: =-G51*G50 -> -6898.3034 | H52: =-H51*H50 -> -7483.1735 | I52: =-I51*I50 -> -8022.8345
B55: CREDIT COST
B57: Credit Cost % (of Advances) | D57: =D59/D58 -> 0.015699189 | E57: =E59/E58 -> 0.023071043 | F57: =F59/F58 -> 0.033506038 | G57: =Assumptions!D14 -> 0.018 | H57: =Assumptions!E14 -> 0.015 | I57: =Assumptions!F14 -> 0.013
B58: Average Advances | D58: =(60005+Financials!D56)/2 -> 65095.718 | E58: =(Financials!D56+Financials!E56)/2 -> 77086.675 | F58: =(Financials!E56+Financials!F56)/2 -> 88302.591 | G58: =(G29+F29)/2 -> 98175.363 | H58: =(H29+G29)/2 -> 110475.07 | I58: =(I29+H29)/2 -> 124836.83
B59: Credit Provisions | D59: =ABS(Financials!D29) -> 1021.95 | E59: =ABS(Financials!E29) -> 1778.47 | F59: =ABS(Financials!F29) -> 2958.67 | G59: =G58*G57 -> 1767.1565 | H59: =H58*H57 -> 1657.126 | I59: =I58*I57 -> 1622.8788
B62: RISK WEIGHTED ASSETS
B64: RWA / Advances % | D64: =D66/D65 -> 1.2130199 | E64: =E66/E65 -> 1.1743462 | F64: =F66/F65 -> 1.1318608 | G64: =Assumptions!D24 -> 1.1 | H64: =Assumptions!E24 -> 1.1 | I64: =Assumptions!F24 -> 1.1
B65: Advances | D65: =Financials!D56 -> 70186.435 | E65: =Financials!E56 -> 83986.915 | F65: =Financials!F56 -> 92618.267 | G65: =G8 -> 103732.46 | H65: =H8 -> 117217.68 | I65: =I8 -> 132455.98
B66: Risk Weighted Assets | D66: =Financials!D71 -> 85137.54 | E66: =Financials!E71 -> 98629.71 | F66: =Financials!F71 -> 104830.98 | G66: =G65*G64 -> 114105.71 | H66: =H65*H64 -> 128939.45 | I66: =I65*I64 -> 145701.57
B69: CAPITAL ADEQUACY
B71: Equity (Roll Forwarded) | D71: =Financials!D43 -> 13525.659 | E71: =Financials!E43 -> 14837.437 | F71: =Financials!F43 -> 15669.525 | G71: =G86 -> 17293.677 | H71: =H86 -> 19417.608 | I71: =I86 -> 21992.465
...

Sheet Assumptions
B2: ASSUMPTIONS AND DRIVERS
B4: Driver Name | C4: Units | D4: FY26E | E4: FY27E | F4: FY28E | G4: Terminal
B5: GROWTH ASSUMPTIONS
B6: Loan Growth % | D6: 0.12 | E6: 0.13 | F6: 0.13 | G6: 0.1
B7: Deposit Growth % | D7: 0.11 | E7: 0.12 | F7: 0.12 | G7: 0.09
B8: investment Growth % | D8: 0.07 | E8: 0.07 | F8: 0.07 | G8: 0.05
B9: Other Assets Growth % | D9: 0.1 | E9: 0.1 | F9: 0.1 | G9: 0.06
B11: PROFITABILITY DRIVERS
B12: Net Interest Margin % | D12: 0.053 | E12: 0.0525 | F12: 0.052 | G12: 0.05
B13: Cost To Income Ratio % | D13: 0.62 | E13: 0.6 | F13: 0.58 | G13: 0.56
B14: Credit cost % (Advances) | D14: 0.018 | E14: 0.015 | F14: 0.013 | G14: 0.012
B15: Non Interest Income / Earning Assets % | D15: 0.029 | E15: 0.03 | F15: 0.03 | G15: 0.03
B17: TAX AND OUTPUT
B18: Effective Tax Rate % | D18: 0.25 | E18: 0.25 | F18: 0.25 | G18: 0.25
B19: Dividend Payout Ratio % | D19: 0.12 | E19: 0.15 | F19: 0.18 | G19: 0.25
B21: CAPITAL AND REGULATORY
B22: Target CAR % | D22: 0.15 | E22: 0.15 | F22: 0.15 | G22: 0.15
B23: Target CET1 % | D23: 0.14 | E23: 0.14 | F23: 0.14 | G23: 0.14
B24: RWA / Advances % | D24: 1.1 | E24: 1.1 | F24: 1.1 | G24: 1.1
B26: VALUATION
B27: Cost of Equity % | D27: 0.135
B28: Terminal Growth % | D28: 0.04
B30: YEILD
B31: Yield on Advances | D31: =Financials!F6/((Financials!F56+Financials!E56)/2) -> 0.12711698 | E31: 0.125 | F31: 0.123
B32: Yield on Investment | D32: =Financials!F7/((Financials!F57+Financials!E57)/2) -> 0.069742684 | E32: 0.068 | F32: 0.067
B33: Yield on Bank | D33: 0.06 | E33: 0.06 | F33: 0.06

Sheet DDM
B2: RBL BANK - DIVIDEND DISCOUNT MODEL
A6: ASSUMPTIONS
A7: Item | B7: Value
A8: Cost of Equity | B8: =B35 -> 0.135
A9: Terminal Growth | B9: =B36 -> 0.04
A12: DIVIDENDS
A13: Year | B13: FY26E | C13: FY27E | D13: FY28E
A14: Dividends | B14: =-1*Schedule!G83 -> 221.47523 | C14: =-1*Schedule!H83 -> 374.81133 | D14: =-1*Schedule!I83 -> 565.21261
A15: Discount Factor | B15: =1/(1+$B$8) -> 0.88105727 | C15: =1/(1+$B$8)^2 -> 0.77626191 | D15: =1/(1+$B$8)^3 -> 0.6839312
A16: PV of Dividends | B16: =B15*B14 -> 195.13236 | C16: =C15*C14 -> 290.95176 | D16: =D15*D14 -> 386.56654
J17: SENSITIVITY ANALYSIS
K19: Cost of Equity
A20: TERMINAL VALUE
A21: Item | B21: Value | I21: =DDM!B32 -> 83.717085 | J21: 0.125 | K21: =Assumptions!D27 -> 0.135 | L21: 0.145
A22: Terminal Value | B22: =D14*(1+B9)/(B8-B9) -> 6187.5906 | I22: 0.03 | J22: 85.183304 | K22: 76.503271 | L22: 69.344909
A23: Discount Factor (FY28) | B23: =D15 -> 0.6839312 | G23: Terminal Growth | I23: =Assumptions!D28 -> 0.04 | J23: 94.253611 | K23: 83.717085 | L23: 75.20051
A24: PV of Terminal Value | B24: =B23*B22 -> 4231.8863 | I24: 0.05 | J24: 105.74267 | K24: 92.628267 | L24: 82.288869
A27: VALUATION | I27: Base Case: Cost of Equity = 13.5%, Terminal Growth = 4.0%
A28: Item | B28: Value
A29: Total PV of Dividends | B29: =SUM(B16:D16) -> 872.65066
A30: Equity Value | B30: =B29+B24 -> 5104.5369
A31: Shares Outstanding | B31: =Financials!F34 -> 609736584
A32: Implied Share Price | B32: =(B30*10000000)/B31 -> 83.717085
A35: Z1 | B35: =Assumptions!D27 -> 0.135
A36: Z2 | B36: =Assumptions!D28 -> 0.04
